Workbook
Name DateDeath: 'Loyd List 1-190 - Edit'!$C$1:$O$184
Name Generation: 'Loyd List 1-190 - Edit'!$A$1:$B$184
Name Loydname: 'Loyd List 1-190 - Edit'!$C$1:$Q$184
Name namewithfather: 'Loyd List 1-190 - Edit'!$P$1:$R$184

Sheet Data check lookup table
A1: Loyd # | F1: Contacting responsibility | H1: From meeting Domininc, Jeremy & Rick
A2: 1 | B2: =COUNTIF('Loyd List 1-190 - Edit'!$R$3:$R$184,'Data check lookup table'!A2) -> 7 | D2: =COUNTIF(B2:B173,">0") -> 1 | G2: Loyd ## | H2: Name | I2: Father's Loyd # | J2: Father's Name | K2: GParent # | L2: GParent Name | M2: 2000 Address | N2: Age - Current | O2: Number of Kids in 2000 | P2: Establishing Contact | Q2: Landline | R2: Mobile | S2: Email | T2: Postal Address in 2021 | U2: Comments
A3: =#REF!+1 -> #REF! | B3: =COUNTIF('Loyd List 1-190 - Edit'!$R$3:$R$184,'Data check lookup table'!A3) -> 0 | G3: 109 | H3: =VLOOKUP(G3,namewithfather,2,FALSE) -> Margaret (109): 1932– | I3: =VLOOKUP(G3,namewithfather,3,FALSE) -> 80 | J3: =VLOOKUP(I3,namewithfather,2,FALSE) -> Eric (80): 1894–1963 | K3: =VLOOKUP(I3,namewithfather,3,FALSE) -> 29 | L3: =VLOOKUP(K3,namewithfather,2,FALSE) -> Arthur (29): 1845–1930 | M3: =VLOOKUP(G3,'Loyd List 1-190 - Edit'!$P$3:$AN$184,25,FALSE) -> 1 | N3: =VLOOKUP(G3,'Loyd List 1-190 - Edit'!$P$3:$AGI$184,26,FALSE) -> 90 | O3: =VLOOKUP(G3,'Loyd List 1-190 - Edit'!$P$3:$AM$184,22,FALSE) -> 3 | P3: Jeremy | S3: mantlehill@aol.com | V3: mantlehill@aol.com
A4: =A3+1 -> #REF! | B4: =COUNTIF('Loyd List 1-190 - Edit'!$R$3:$R$184,'Data check lookup table'!A4) -> 0 | G4: 110 | H4: =VLOOKUP(G4,namewithfather,2,FALSE) -> Jean (110): 1933– | I4: =VLOOKUP(G4,namewithfather,3,FALSE) -> 80 | J4: =VLOOKUP(I4,namewithfather,2,FALSE) -> Eric (80): 1894–1963 | K4: =VLOOKUP(I4,namewithfather,3,FALSE) -> 29 | L4: =VLOOKUP(K4,namewithfather,2,FALSE) -> Arthur (29): 1845–1930 | M4: =VLOOKUP(G4,'Loyd List 1-190 - Edit'!$P$3:$AN$184,25,FALSE) -> 1 | N4: =VLOOKUP(G4,'Loyd List 1-190 - Edit'!$P$3:$AGI$184,26,FALSE) -> 88 | O4: =VLOOKUP(G4,'Loyd List 1-190 - Edit'!$P$3:$AM$184,22,FALSE) -> 8 | P4: Jeremy | S4: mantlehill@aol.com | V4: mantlehill@aol.com
A5: =A4+1 -> #REF! | B5: =COUNTIF('Loyd List 1-190 - Edit'!$R$3:$R$184,'Data check lookup table'!A5) -> 0 | G5: 114 | H5: =VLOOKUP(G5,namewithfather,2,FALSE) -> Michael (114): 1938– | I5: =VLOOKUP(G5,namewithfather,3,FALSE) -> 80 | J5: =VLOOKUP(I5,namewithfather,2,FALSE) -> Eric (80): 1894–1963 | K5: =VLOOKUP(I5,namewithfather,3,FALSE) -> 29 | L5: =VLOOKUP(K5,namewithfather,2,FALSE) -> Arthur (29): 1845–1930 | M5: =VLOOKUP(G5,'Loyd List 1-190 - Edit'!$P$3:$AN$184,25,FALSE) -> 1 | N5: =VLOOKUP(G5,'Loyd List 1-190 - Edit'!$P$3:$AGI$184,26,FALSE) -> 83 | O5: =VLOOKUP(G5,'Loyd List 1-190 - Edit'!$P$3:$AM$184,22,FALSE) -> 8 | P5: Jeremy | S5: loydthreepwood@gmail.com | V5: loydthreepwood@gmail.com
A6: =A5+1 -> #REF! | B6: =COUNTIF('Loyd List 1-190 - Edit'!$R$3:$R$184,'Data check lookup table'!A6) -> 0 | G6: 119 | H6: =VLOOKUP(G6,namewithfather,2,FALSE) -> Peter (119): 1942– | I6: =VLOOKUP(G6,namewithfather,3,FALSE) -> 80 | J6: =VLOOKUP(I6,namewithfather,2,FALSE) -> Eric (80): 1894–1963 | K6: =VLOOKUP(I6,namewithfather,3,FALSE) -> 29 | L6: =VLOOKUP(K6,namewithfather,2,FALSE) -> Arthur (29): 1845–1930 | M6: =VLOOKUP(G6,'Loyd List 1-190 - Edit'!$P$3:$AN$184,25,FALSE) -> 1 | N6: =VLOOKUP(G6,'Loyd List 1-190 - Edit'!$P$3:$AGI$184,26,FALSE) -> 79 | O6: =VLOOKUP(G6,'Loyd List 1-190 - Edit'!$P$3:$AM$184,22,FALSE) -> 9 | P6: Jeremy | S6: mantlehill@aol.com | V6: mantlehill@aol.com
A7: =A6+1 -> #REF! | B7: =COUNTIF('Loyd List 1-190 - Edit'!$R$3:$R$184,'Data check lookup table'!A7) -> 0 | G7: 102 | H7: =VLOOKUP(G7,namewithfather,2,FALSE) -> Zelda (102): 1923–2014 | I7: =VLOOKUP(G7,namewithfather,3,FALSE) -> 62 | J7: =VLOOKUP(I7,namewithfather,2,FALSE) -> Bobby (62): 1887–1977 | K7: =VLOOKUP(I7,namewithfather,3,FALSE) -> 30 | L7: =VLOOKUP(K7,namewithfather,2,FALSE) -> Archie (30): 1847–1922 | M7: =VLOOKUP(G7,'Loyd List 1-190 - Edit'!$P$3:$AN$184,25,FALSE) -> 30 | N7: =VLOOKUP(G7,'Loyd List 1-190 - Edit'!$P$3:$AGI$184,26,FALSE) -> 90 | O7: =VLOOKUP(G7,'Loyd List 1-190 - Edit'!$P$3:$AM$184,22,FALSE) -> 5 | P7: Jeremy | S7: tessdunlop@gmail.com; celinadunlop@btinternet.com
A8: =A7+1 -> #REF! | B8: =COUNTIF('Loyd List 1-190 - Edit'!$R$3:$R$184,'Data check lookup table'!A8) -> 0 | G8: 98 | H8: =VLOOKUP(G8,namewithfather,2,FALSE) -> Peter (98): 1922–2022 | I8: =VLOOKUP(G8,namewithfather,3,FALSE) -> 77 | J8: =VLOOKUP(I8,namewithfather,2,FALSE) -> Wilfrid (77): 1893–1971 | K8: =VLOOKUP(I8,namewithfather,3,FALSE) -> 30 | L8: =VLOOKUP(K8,namewithfather,2,FALSE) -> Archie (30): 1847–1922 | M8: =VLOOKUP(G8,'Loyd List 1-190 - Edit'!$P$3:$AN$184,25,FALSE) -> 13 | N8: =VLOOKUP(G8,'Loyd List 1-190 - Edit'!$P$3:$AGI$184,26,FALSE) -> 99 | O8: =VLOOKUP(G8,'Loyd List 1-190 - Edit'!$P$3:$AM$184,22,FALSE) -> 8 | P8: Jeremy | S8: rosemaryloyd@gmail.com | V8: rosemaryloyd@gmail.com
A9: =A8+1 -> #REF! | B9: =COUNTIF('Loyd List 1-190 - Edit'!$R$3:$R$184,'Data check lookup table'!A9) -> 0 | G9: 106 | H9: =VLOOKUP(G9,namewithfather,2,FALSE) -> Denise (106): 1928– | I9: =VLOOKUP(G9,namewithfather,3,FALSE) -> 77 | J9: =VLOOKUP(I9,namewithfather,2,FALSE) -> Wilfrid (77): 1893–1971 | K9: =VLOOKUP(I9,namewithfather,3,FALSE) -> 30 | L9: =VLOOKUP(K9,namewithfather,2,FALSE) -> Archie (30): 1847–1922 | M9: =VLOOKUP(G9,'Loyd List 1-190 - Edit'!$P$3:$AN$184,25,FALSE) -> 1 | N9: =VLOOKUP(G9,'Loyd List 1-190 - Edit'!$P$3:$AGI$184,26,FALSE) -> 93 | O9: =VLOOKUP(G9,'Loyd List 1-190 - Edit'!$P$3:$AM$184,22,FALSE) -> 11 | P9: Jeremy | S9: rosemaryloyd@gmail.com | V9: rosemaryloyd@gmail.com
A10: =#REF!+1 -> #REF! | B10: =COUNTIF('Loyd List 1-190 - Edit'!$R$3:$R$184,'Data check lookup table'!A10) -> 0 | G10: 116 | H10: =VLOOKUP(G10,namewithfather,2,FALSE) -> Peggy (116): 1939– | I10: =VLOOKUP(G10,namewithfather,3,FALSE) -> 55 | J10: =VLOOKUP(I10,namewithfather,2,FALSE) -> Dick (55): 1882–1950 | K10: =VLOOKUP(I10,namewithfather,3,FALSE) -> 35 | L10: =VLOOKUP(K10,namewithfather,2,FALSE) -> Lewis (35): 1852–1908 | M10: =VLOOKUP(G10,'Loyd List 1-190 - Edit'!$P$3:$AN$184,25,FALSE) -> 1 | N10: =VLOOKUP(G10,'Loyd List 1-190 - Edit'!$P$3:$AGI$184,26,FALSE) -> 82 | O10: =VLOOKUP(G10,'Loyd List 1-190 - Edit'!$P$3:$AM$184,22,FALSE) -> 11 | P10: Jeremy | S10: patrickloyd@cwgsy.net | V10: patrickloyd@cwgsy.net
A11: =A10+1 -> #REF! | B11: =COUNTIF('Loyd List 1-190 - Edit'!$R$3:$R$184,'Data check lookup table'!A11) -> 0 | G11: 117 | H11: =VLOOKUP(G11,namewithfather,2,FALSE) -> Patrick (117): 1942– | I11: =VLOOKUP(G11,namewithfather,3,FALSE) -> 55 | J11: =VLOOKUP(I11,namewithfather,2,FALSE) -> Dick (55): 1882–1950 | K11: =VLOOKUP(I11,namewithfather,3,FALSE) -> 35 | L11: =VLOOKUP(K11,namewithfather,2,FALSE) -> Lewis (35): 1852–1908 | M11: =VLOOKUP(G11,'Loyd List 1-190 - Edit'!$P$3:$AN$184,25,FALSE) -> 1 | N11: =VLOOKUP(G11,'Loyd List 1-190 - Edit'!$P$3:$AGI$184,26,FALSE) -> 80 | O11: =VLOOKUP(G11,'Loyd List 1-190 - Edit'!$P$3:$AM$184,22,FALSE) -> 3 | P11: Jeremy | S11: patrickloyd@cwgsy.net | V11: patrickloyd@cwgsy.net
A12: =A11+1 -> #REF! | B12: =COUNTIF('Loyd List 1-190 - Edit'!$R$3:$R$184,'Data check lookup table'!A12) -> 0 | G12: 97 | H12: =VLOOKUP(G12,namewithfather,2,FALSE) -> Audrey (97): 1922–2005 | I12: =VLOOKUP(G12,namewithfather,3,FALSE) -> 53 | J12: =VLOOKUP(I12,namewithfather,2,FALSE) -> Edward (53): 1881–1962 | K12: =VLOOKUP(I12,namewithfather,3,FALSE) -> 41 | L12: =VLOOKUP(K12,namewithfather,2,FALSE) -> Frederic (41): 1856–1936 | M12: =VLOOKUP(G12,'Loyd List 1-190 - Edit'!$P$3:$AN$184,25,FALSE) -> 4 | N12: =VLOOKUP(G12,'Loyd List 1-190 - Edit'!$P$3:$AGI$184,26,FALSE) -> 83 | O12: =VLOOKUP(G12,'Loyd List 1-190 - Edit'!$P$3:$AM$184,22,FALSE) -> 4 | P12: Rick | S12: Deceased
A13: =#REF!+1 -> #REF! | B13: =COUNTIF('Loyd List 1-190 - Edit'!$R$3:$R$184,'Data check lookup table'!A13) -> 0 | G13: 127 | H13: =VLOOKUP(G13,namewithfather,2,FALSE) -> Vivian (127): 1951– | I13: =VLOOKUP(G13,namewithfather,3,FALSE) -> 78 | J13: =VLOOKUP(I13,namewithfather,2,FALSE) -> Vivian (78): 1894–1972 | K13: =VLOOKUP(I13,namewithfather,3,FALSE) -> 46 | L13: =VLOOKUP(K13,namewithfather,2,FALSE) -> William (46): 1863–1923 | M13: =VLOOKUP(G13,'Loyd List 1-190 - Edit'!$P$3:$AN$184,25,FALSE) -> 1 | N13: =VLOOKUP(G13,'Loyd List 1-190 - Edit'!$P$3:$AGI$184,26,FALSE) -> 70 | O13: =VLOOKUP(G13,'Loyd List 1-190 - Edit'!$P$3:$AM$184,22,FALSE) -> 11 | P13: Dominic | S13: victoryyardiow@gmail.com | V13: victoryyardiow@gmail.com
A14: =A13+1 -> #REF! | B14: =COUNTIF('Loyd List 1-190 - Edit'!$R$3:$R$184,'Data check lookup table'!A14) -> 0 | G14: 140 | H14: =VLOOKUP(G14,namewithfather,2,FALSE) -> Ginie (140): 1961– | I14: =VLOOKUP(G14,namewithfather,3,FALSE) -> 78 | J14: =VLOOKUP(I14,namewithfather,2,FALSE) -> Vivian (78): 1894–1972 | K14: =VLOOKUP(I14,namewithfather,3,FALSE) -> 46 | L14: =VLOOKUP(K14,namewithfather,2,FALSE) -> William (46): 1863–1923 | M14: =VLOOKUP(G14,'Loyd List 1-190 - Edit'!$P$3:$AN$184,25,FALSE) -> 1 | N14: =VLOOKUP(G14,'Loyd List 1-190 - Edit'!$P$3:$AGI$184,26,FALSE) -> 60 | O14: =VLOOKUP(G14,'Loyd List 1-190 - Edit'!$P$3:$AM$184,22,FALSE) -> 8 | P14: Dominic | S14: cherrytreefarms@gmail.com | V14: cherrytreefarms@gmail.com
A15: =A14+1 -> #REF! | B15: =COUNTIF('Loyd List 1-190 - Edit'!$R$3:$R$184,'Data check lookup table'!A15) -> 0 | G15: 123 | H15: =VLOOKUP(G15,namewithfather,2,FALSE) -> Janet (123): 1949– | I15: =VLOOKUP(G15,namewithfather,3,FALSE) -> 89 | J15: =VLOOKUP(I15,namewithfather,2,FALSE) -> Sir Francis/Frank (89): 1916–2006 | K15: =VLOOKUP(I15,namewithfather,3,FALSE) -> 54 | L15: =VLOOKUP(K15,namewithfather,2,FALSE) -> Alfred (54): 1882–1919 | M15: =VLOOKUP(G15,'Loyd List 1-190 - Edit'!$P$3:$AN$184,25,FALSE) -> 1 | N15: =VLOOKUP(G15,'Loyd List 1-190 - Edit'!$P$3:$AGI$184,26,FALSE) -> 73 | O15: =VLOOKUP(G15,'Loyd List 1-190 - Edit'!$P$3:$AM$184,22,FALSE) -> 5 | P15: Dominic | S15: janetbosman@icloud.com | V15: janetbosman@icloud.com
A16: =A15+1 -> #REF! | B16: =COUNTIF('Loyd List 1-190 - Edit'!$R$3:$R$184,'Data check lookup table'!A16) -> 0 | G16: 129 | H16: =VLOOKUP(G16,namewithfather,2,FALSE) -> Diana (129): 1952– | I16: =VLOOKUP(G16,namewithfather,3,FALSE) -> 89 | J16: =VLOOKUP(I16,namewithfather,2,FALSE) -> Sir Francis/Frank (89): 1916–2006 | K16: =VLOOKUP(I16,namewithfather,3,FALSE) -> 54 | L16: =VLOOKUP(K16,namewithfather,2,FALSE) -> Alfred (54): 1882–1919 | M16: =VLOOKUP(G16,'Loyd List 1-190 - Edit'!$P$3:$AN$184,25,FALSE) -> 1 | N16: =VLOOKUP(G16,'Loyd List 1-190 - Edit'!$P$3:$AGI$184,26,FALSE) -> 70 | O16: =VLOOKUP(G16,'Loyd List 1-190 - Edit'!$P$3:$AM$184,22,FALSE) -> 5 | P16: Dominic | S16: dmsako@shaw.ca | V16: dmsako@shaw.ca
A17: =A16+1 -> #REF! | B17: =COUNTIF('Loyd List 1-190 - Edit'!$R$3:$R$184,'Data check lookup table'!A17) -> 0 | G17: 147 | H17: =VLOOKUP(G17,namewithfather,2,FALSE) -> Susannah (147): 1965– | I17: =VLOOKUP(G17,namewithfather,3,FALSE) -> 117 | J17: =VLOOKUP(I17,namewithfather,2,FALSE) -> Patrick (117): 1942– | K17: =VLOOKUP(I17,namewithfather,3,FALSE) -> 55 | L17: =VLOOKUP(K17,namewithfather,2,FALSE) -> Dick (55): 1882–1950 | M17: =VLOOKUP(G17,'Loyd List 1-190 - Edit'!$P$3:$AN$184,25,FALSE) -> 1 | N17: =VLOOKUP(G17,'Loyd List 1-190 - Edit'!$P$3:$AGI$184,26,FALSE) -> 56 | O17: =VLOOKUP(G17,'Loyd List 1-190 - Edit'!$P$3:$AM$184,22,FALSE) -> 9 | P17: Jeremy | S17: patrickloyd@cwgsy.net | V17: patrickloyd@cwgsy.net
A18: =A17+1 -> #REF! | B18: =COUNTIF('Loyd List 1-190 - Edit'!$R$3:$R$184,'Data check lookup table'!A18) -> 0 | G18: 151 | H18: =VLOOKUP(G18,namewithfather,2,FALSE) -> Elspeth (151): 1967– | I18: =VLOOKUP(G18,namewithfather,3,FALSE) -> 117 | J18: =VLOOKUP(I18,namewithfather,2,FALSE) -> Patrick (117): 1942– | K18: =VLOOKUP(I18,namewithfather,3,FALSE) -> 55 | L18: =VLOOKUP(K18,namewithfather,2,FALSE) -> Dick (55): 1882–1950 | M18: =VLOOKUP(G18,'Loyd List 1-190 - Edit'!$P$3:$AN$184,25,FALSE) -> 1 | N18: =VLOOKUP(G18,'Loyd List 1-190 - Edit'!$P$3:$AGI$184,26,FALSE) -> 55 | O18: =VLOOKUP(G18,'Loyd List 1-190 - Edit'!$P$3:$AM$184,22,FALSE) -> 5 | P18: Jeremy | S18: patrickloyd@cwgsy.net | V18: patrickloyd@cwgsy.net
A19: =A18+1 -> #REF! | B19: =COUNTIF('Loyd List 1-190 - Edit'!$R$3:$R$184,'Data check lookup table'!A19) -> 0 | G19: 153 | H19: =VLOOKUP(G19,namewithfather,2,FALSE) -> Richard (153): 1968– | I19: =VLOOKUP(G19,namewithfather,3,FALSE) -> 117 | J19: =VLOOKUP(I19,namewithfather,2,FALSE) -> Patrick (117): 1942– | K19: =VLOOKUP(I19,namewithfather,3,FALSE) -> 55 | L19: =VLOOKUP(K19,namewithfather,2,FALSE) -> Dick (55): 1882–1950 | M19: =VLOOKUP(G19,'Loyd List 1-190 - Edit'!$P$3:$AN$184,25,FALSE) -> 1 | N19: =VLOOKUP(G19,'Loyd List 1-190 - Edit'!$P$3:$AGI$184,26,FALSE) -> 54 | O19: =VLOOKUP(G19,'Loyd List 1-190 - Edit'!$P$3:$AM$184,22,FALSE) -> 6 | P19: Jeremy | S19: patrickloyd@cwgsy.net | V19: patrickloyd@cwgsy.net
A20: =A19+1 -> #REF! | B20: =COUNTIF('Loyd List 1-190 - Edit'!$R$3:$R$184,'Data check lookup table'!A20) -> 0 | G20: 138 | H20: =VLOOKUP(G20,namewithfather,2,FALSE) -> Thomas (138): 1959– | I20: =VLOOKUP(G20,namewithfather,3,FALSE) -> 100 | J20: =VLOOKUP(I20,namewithfather,2,FALSE) -> Christopher (100): 1923–2013 | K20: =VLOOKUP(I20,namewithfather,3,FALSE) -> 56 | L20: =VLOOKUP(K20,namewithfather,2,FALSE) -> Tommy (56): 1882–1944 | M20: =VLOOKUP(G20,'Loyd List 1-190 - Edit'!$P$3:$AN$184,25,FALSE) -> 1 | N20: =VLOOKUP(G20,'Loyd List 1-190 - Edit'!$P$3:$AGI$184,26,FALSE) -> 63 | O20: =VLOOKUP(G20,'Loyd List 1-190 - Edit'!$P$3:$AM$184,22,FALSE) -> 2 | P20: Jeremy | R20: 07770984123 | S20: tloyd@lockinge-estate.co.uk | U20: 138 | V20: tloyd@lockinge-estate.co.uk
A21: =A20+1 -> #REF! | B21: =COUNTIF('Loyd List 1-190 - Edit'!$R$3:$R$184,'Data check lookup table'!A21) -> 0 | G21: 143 | H21: =VLOOKUP(G21,namewithfather,2,FALSE) -> Harriet (143): 1962– | I21: =VLOOKUP(G21,namewithfather,3,FALSE) -> 100 | J21: =VLOOKUP(I21,namewithfather,2,FALSE) -> Christopher (100): 1923–2013 | K21: =VLOOKUP(I21,namewithfather,3,FALSE) -> 56 | L21: =VLOOKUP(K21,namewithfather,2,FALSE) -> Tommy (56): 1882–1944 | M21: =VLOOKUP(G21,'Loyd List 1-190 - Edit'!$P$3:$AN$184,25,FALSE) -> 1 | N21: =VLOOKUP(G21,'Loyd List 1-190 - Edit'!$P$3:$AGI$184,26,FALSE) -> 60 | O21: =VLOOKUP(G21,'Loyd List 1-190 - Edit'!$P$3:$AM$184,22,FALSE) -> 6 | P21: Jeremy | S21: tloyd@lockinge-estate.co.uk | U21: 138 | V21: tloyd@lockinge-estate.co.uk
A22: =A21+1 -> #REF! | B22: =COUNTIF('Loyd List 1-190 - Edit'!$R$3:$R$184,'Data check lookup table'!A22) -> 0 | G22: 150 | H22: =VLOOKUP(G22,namewithfather,2,FALSE) -> James (150): 1966– | I22: =VLOOKUP(G22,namewithfather,3,FALSE) -> 100 | J22: =VLOOKUP(I22,namewithfather,2,FALSE) -> Christopher (100): 1923–2013 | K22: =VLOOKUP(I22,namewithfather,3,FALSE) -> 56 | L22: =VLOOKUP(K22,namewithfather,2,FALSE) -> Tommy (56): 1882–1944 | M22: =VLOOKUP(G22,'Loyd List 1-190 - Edit'!$P$3:$AN$184,25,FALSE) -> 1 | N22: =VLOOKUP(G22,'Loyd List 1-190 - Edit'!$P$3:$AGI$184,26,FALSE) -> 55 | O22: =VLOOKUP(G22,'Loyd List 1-190 - Edit'!$P$3:$AM$184,22,FALSE) -> 9 | P22: Jeremy | S22: tloyd@lockinge-estate.co.uk | U22: 138 | V22: tloyd@lockinge-estate.co.uk
A23: =A22+1 -> #REF! | B23: =COUNTIF('Loyd List 1-190 - Edit'!$R$3:$R$184,'Data check lookup table'!A23) -> 0 | G23: 120 | H23: =VLOOKUP(G23,namewithfather,2,FALSE) -> Caroline (120): 1947–2022 | I23: =VLOOKUP(G23,namewithfather,3,FALSE) -> 96 | J23: =VLOOKUP(I23,namewithfather,2,FALSE) -> Edward (96): 1921–1977 | K23: =VLOOKUP(I23,namewithfather,3,FALSE) -> 66 | L23: =VLOOKUP(K23,namewithfather,2,FALSE) -> William (66): 1889–1947 | M23: =VLOOKUP(G23,'Loyd List 1-190 - Edit'!$P$3:$AN$184,25,FALSE) -> 13 | N23: =VLOOKUP(G23,'Loyd List 1-190 - Edit'!$P$3:$AGI$184,26,FALSE) -> 75 | O23: =VLOOKUP(G23,'Loyd List 1-190 - Edit'!$P$3:$AM$184,22,FALSE) -> 1 | P23: Dominic | S23: Deceased | V23: david.loyd@hotmail.com
A24: =A23+1 -> #REF! | B24: =COUNTIF('Loyd List 1-190 - Edit'!$R$3:$R$184,'Data check lookup table'!A24) -> 0 | G24: 121 | H24: =VLOOKUP(G24,namewithfather,2,FALSE) -> David (121): 1949– | I24: =VLOOKUP(G24,namewithfather,3,FALSE) -> 96 | J24: =VLOOKUP(I24,namewithfather,2,FALSE) -> Edward (96): 1921–1977 | K24: =VLOOKUP(I24,namewithfather,3,FALSE) -> 66 | L24: =VLOOKUP(K24,namewithfather,2,FALSE) -> William (66): 1889–1947 | M24: =VLOOKUP(G24,'Loyd List 1-190 - Edit'!$P$3:$AN$184,25,FALSE) -> 1 | N24: =VLOOKUP(G24,'Loyd List 1-190 - Edit'!$P$3:$AGI$184,26,FALSE) -> 73 | O24: =VLOOKUP(G24,'Loyd List 1-190 - Edit'!$P$3:$AM$184,22,FALSE) -> 1 | P24: Dominic | S24: david.loyd@hotmail.com | V24: david.loyd@hotmail.com
A25: =A24+1 -> #REF! | B25: =COUNTIF('Loyd List 1-190 - Edit'!$R$3:$R$184,'Data check lookup table'!A25) -> 0 | G25: 137 | H25: =VLOOKUP(G25,namewithfather,2,FALSE) -> Henrietta (137): 1959– | I25: =VLOOKUP(G25,namewithfather,3,FALSE) -> 99 | J25: =VLOOKUP(I25,namewithfather,2,FALSE) -> Peter (99): 1923–1974 | K25: =VLOOKUP(I25,namewithfather,3,FALSE) -> 66 | L25: =VLOOKUP(K25,namewithfather,2,FALSE) -> William (66): 1889–1947 | M25: =VLOOKUP(G25,'Loyd List 1-190 - Edit'!$P$3:$AN$184,25,FALSE) -> 1 | N25: =VLOOKUP(G25,'Loyd List 1-190 - Edit'!$P$3:$AGI$184,26,FALSE) -> 63 | O25: =VLOOKUP(G25,'Loyd List 1-190 - Edit'!$P$3:$AM$184,22,FALSE) -> 1 | P25: Dominic | R25: 07831134130 | S25: henrietta@cazloyd.com | V25: henrietta@cazloyd.com
A26: =A25+1 -> #REF! | B26: =COUNTIF('Loyd List 1-190 - Edit'!$R$3:$R$184,'Data check lookup table'!A26) -> 0 | G26: 144 | H26: =VLOOKUP(G26,namewithfather,2,FALSE) -> Andrew (144): 1962– | I26: =VLOOKUP(G26,namewithfather,3,FALSE) -> 99 | J26: =VLOOKUP(I26,namewithfather,2,FALSE) -> Peter (99): 1923–1974 | K26: =VLOOKUP(I26,namewithfather,3,FALSE) -> 66 | L26: =VLOOKUP(K26,namewithfather,2,FALSE) -> William (66): 1889–1947 | M26: =VLOOKUP(G26,'Loyd List 1-190 - Edit'!$P$3:$AN$184,25,FALSE) -> 1 | N26: =VLOOKUP(G26,'Loyd List 1-190 - Edit'!$P$3:$AGI$184,26,FALSE) -> 59 | O26: =VLOOKUP(G26,'Loyd List 1-190 - Edit'!$P$3:$AM$184,22,FALSE) -> 11 | P26: Dominic | R26: 07715122288 | S26: andrew@ltrcastles.com | V26: andrew@ltrcastles.com
A27: =A26+1 -> #REF! | B27: =COUNTIF('Loyd List 1-190 - Edit'!$R$3:$R$184,'Data check lookup table'!A27) -> 0 | G27: 124 | H27: =VLOOKUP(G27,namewithfather,2,FALSE) -> Rob (124): 1949– | I27: =VLOOKUP(G27,namewithfather,3,FALSE) -> 94 | J27: =VLOOKUP(I27,namewithfather,2,FALSE) -> Alwyne (94): 1920–2014 | K27: =VLOOKUP(I27,namewithfather,3,FALSE) -> 68 | L27: =VLOOKUP(K27,namewithfather,2,FALSE) -> Cecil (68): 1890–1963 | M27: =VLOOKUP(G27,'Loyd List 1-190 - Edit'!$P$3:$AN$184,25,FALSE) -> 1 | N27: =VLOOKUP(G27,'Loyd List 1-190 - Edit'!$P$3:$AGI$184,26,FALSE) -> 72 | O27: =VLOOKUP(G27,'Loyd List 1-190 - Edit'!$P$3:$AM$184,22,FALSE) -> 7 | P27: Dominic | S27: robloyd@icloud.com | V27: justtheonetoo@gmail.com
A28: =A27+1 -> #REF! | B28: =COUNTIF('Loyd List 1-190 - Edit'!$R$3:$R$184,'Data check lookup table'!A28) -> 0 | G28: 126 | H28: =VLOOKUP(G28,namewithfather,2,FALSE) -> Paddy (126): 1951– | I28: =VLOOKUP(G28,namewithfather,3,FALSE) -> 94 | J28: =VLOOKUP(I28,namewithfather,2,FALSE) -> Alwyne (94): 1920–2014 | K28: =VLOOKUP(I28,namewithfather,3,FALSE) -> 68 | L28: =VLOOKUP(K28,namewithfather,2,FALSE) -> Cecil (68): 1890–1963 | M28: =VLOOKUP(G28,'Loyd List 1-190 - Edit'!$P$3:$AN$184,25,FALSE) -> 1 | N28: =VLOOKUP(G28,'Loyd List 1-190 - Edit'!$P$3:$AGI$184,26,FALSE) -> 71 | O28: =VLOOKUP(G28,'Loyd List 1-190 - Edit'!$P$3:$AM$184,22,FALSE) -> 6 | P28: Dominic | S28: paddyloyd@talk21.com | V28: paddyloyd@talk21.com
A29: =A28+1 -> #REF! | B29: =COUNTIF('Loyd List 1-190 - Edit'!$R$3:$R$184,'Data check lookup table'!A29) -> 0 | G29: 131 | H29: =VLOOKUP(G29,namewithfather,2,FALSE) -> Dominic (131): 1953– | I29: =VLOOKUP(G29,namewithfather,3,FALSE) -> 94 | J29: =VLOOKUP(I29,namewithfather,2,FALSE) -> Alwyne (94): 1920–2014 | K29: =VLOOKUP(I29,namewithfather,3,FALSE) -> 68 | L29: =VLOOKUP(K29,namewithfather,2,FALSE) -> Cecil (68): 1890–1963 | M29: =VLOOKUP(G29,'Loyd List 1-190 - Edit'!$P$3:$AN$184,25,FALSE) -> 1 | N29: =VLOOKUP(G29,'Loyd List 1-190 - Edit'!$P$3:$AGI$184,26,FALSE) -> 69 | O29: =VLOOKUP(G29,'Loyd List 1-190 - Edit'!$P$3:$AM$184,22,FALSE) -> 3 | P29: Dominic | S29: dominicloyd@btinternet.com | T29: 126 Princess Anne Road, Boston, Lincolnshire, PE21 9AQ. | V29: dominicloyd@btinternet.com
A30: =A29+1 -> #REF! | B30: =COUNTIF('Loyd List 1-190 - Edit'!$R$3:$R$184,'Data check lookup table'!A30) -> 0 | G30: 136 | H30: =VLOOKUP(G30,namewithfather,2,FALSE) -> Tim (136): 1957– | I30: =VLOOKUP(G30,namewithfather,3,FALSE) -> 94 | J30: =VLOOKUP(I30,namewithfather,2,FALSE) -> Alwyne (94): 1920–2014 | K30: =VLOOKUP(I30,namewithfather,3,FALSE) -> 68 | L30: =VLOOKUP(K30,namewithfather,2,FALSE) -> Cecil (68): 1890–1963 | M30: =VLOOKUP(G30,'Loyd List 1-190 - Edit'!$P$3:$AN$184,25,FALSE) -> 1 | N30: =VLOOKUP(G30,'Loyd List 1-190 - Edit'!$P$3:$AGI$184,26,FALSE) -> 65 | O30: =VLOOKUP(G30,'Loyd List 1-190 - Edit'!$P$3:$AM$184,22,FALSE) -> 6 | P30: Dominic | S30: tim.loyd@btinternet.com | V30: tim.loyd@btinternet.com
A31: =A30+1 -> #REF! | B31: =COUNTIF('Loyd List 1-190 - Edit'!$R$3:$R$184,'Data check lookup table'!A31) -> 0 | G31: 139 | H31: =VLOOKUP(G31,namewithfather,2,FALSE) -> Alex (139): 1959– | I31: =VLOOKUP(G31,namewithfather,3,FALSE) -> 94 | J31: =VLOOKUP(I31,namewithfather,2,FALSE) -> Alwyne (94): 1920–2014 | K31: =VLOOKUP(I31,namewithfather,3,FALSE) -> 68 | L31: =VLOOKUP(K31,namewithfather,2,FALSE) -> Cecil (68): 1890–1963 | M31: =VLOOKUP(G31,'Loyd List 1-190 - Edit'!$P$3:$AN$184,25,FALSE) -> 1 | N31: =VLOOKUP(G31,'Loyd List 1-190 - Edit'!$P$3:$AGI$184,26,FALSE) -> 63 | O31: =VLOOKUP(G31,'Loyd List 1-190 - Edit'!$P$3:$AM$184,22,FALSE) -> 3 | P31: Dominic | S31: abloyd@aol.co.uk | V31: abloyd@aol.co.uk
A32: =A31+1 -> #REF! | B32: =COUNTIF('Loyd List 1-190 - Edit'!$R$3:$R$184,'Data check lookup table'!A32) -> 0 | G32: 142 | H32: =VLOOKUP(G32,namewithfather,2,FALSE) -> Rick (142): 1962– | I32: =VLOOKUP(G32,namewithfather,3,FALSE) -> 94 | J32: =VLOOKUP(I32,namewithfather,2,FALSE) -> Alwyne (94): 1920–2014 | K32: =VLOOKUP(I32,namewithfather,3,FALSE) -> 68 | L32: =VLOOKUP(K32,namewithfather,2,FALSE) -> Cecil (68): 1890–1963 | M32: =VLOOKUP(G32,'Loyd List 1-190 - Edit'!$P$3:$AN$184,25,FALSE) -> 1 | N32: =VLOOKUP(G32,'Loyd List 1-190 - Edit'!$P$3:$AGI$184,26,FALSE) -> 60 | O32: =VLOOKUP(G32,'Loyd List 1-190 - Edit'!$P$3:$AM$184,22,FALSE) -> 3 | P32: Dominic | S32: rick@changebynumbers.com | V32: rick@changebynumbers.com
A33: =A32+1 -> #REF! | B33: =COUNTIF('Loyd List 1-190 - Edit'!$R$3:$R$184,'Data check lookup table'!A33) -> 0 | G33: 125 | H33: =VLOOKUP(G33,namewithfather,2,FALSE) -> Rona (125): 1951– | I33: =VLOOKUP(G33,namewithfather,3,FALSE) -> 86 | J33: =VLOOKUP(I33,namewithfather,2,FALSE) -> Peter (86): 1913–2008 | K33: =VLOOKUP(I33,namewithfather,3,FALSE) -> 71 | L33: =VLOOKUP(K33,namewithfather,2,FALSE) -> Arthur (71): 1890–1974 | M33: =VLOOKUP(G33,'Loyd List 1-190 - Edit'!$P$3:$AN$184,25,FALSE) -> 1 | N33: =VLOOKUP(G33,'Loyd List 1-190 - Edit'!$P$3:$AGI$184,26,FALSE) -> 71 | O33: =VLOOKUP(G33,'Loyd List 1-190 - Edit'!$P$3:$AM$184,22,FALSE) -> 2 | P33: Dominic | S33: jockronahawkey@hotmail.com | V33: jockronahawkey@hotmail.com
A34: =A33+1 -> #REF! | B34: =COUNTIF('Loyd List 1-190 - Edit'!$R$3:$R$184,'Data check lookup table'!A34) -> 0 | G34: 130 | H34: =VLOOKUP(G34,namewithfather,2,FALSE) -> David (130): 1952– | I34: =VLOOKUP(G34,namewithfather,3,FALSE) -> 86 | J34: =VLOOKUP(I34,namewithfather,2,FALSE) -> Peter (86): 1913–2008 | K34: =VLOOKUP(I34,namewithfather,3,FALSE) -> 71 | L34: =VLOOKUP(K34,namewithfather,2,FALSE) -> Arthur (71): 1890–1974 | M34: =VLOOKUP(G34,'Loyd List 1-190 - Edit'!$P$3:$AN$184,25,FALSE) -> 1 | N34: =VLOOKUP(G34,'Loyd List 1-190 - Edit'!$P$3:$AGI$184,26,FALSE) -> 70 | O34: =VLOOKUP(G34,'Loyd List 1-190 - Edit'!$P$3:$AM$184,22,FALSE) -> 6 | P34: Dominic | S34: jdloyd1783@gmail.com | V34: jdloyd1783@gmail.com
A35: =A34+1 -> #REF! | B35: =COUNTIF('Loyd List 1-190 - Edit'!$R$3:$R$184,'Data check lookup table'!A35) -> 0 | G35: 135 | H35: =VLOOKUP(G35,namewithfather,2,FALSE) -> Jim (135): 1955– | I35: =VLOOKUP(G35,namewithfather,3,FALSE) -> 86 | J35: =VLOOKUP(I35,namewithfather,2,FALSE) -> Peter (86): 1913–2008 | K35: =VLOOKUP(I35,namewithfather,3,FALSE) -> 71 | L35: =VLOOKUP(K35,namewithfather,2,FALSE) -> Arthur (71): 1890–1974 | M35: =VLOOKUP(G35,'Loyd List 1-190 - Edit'!$P$3:$AN$184,25,FALSE) -> 1 | N35: =VLOOKUP(G35,'Loyd List 1-190 - Edit'!$P$3:$AGI$184,26,FALSE) -> 66 | O35: =VLOOKUP(G35,'Loyd List 1-190 - Edit'!$P$3:$AM$184,22,FALSE) -> 8 | P35: Dominic | S35: jimbrendaloyd1@gmail.com | V35: jimbrendaloyd1@gmail.com
A36: =A35+1 -> #REF! | B36: =COUNTIF('Loyd List 1-190 - Edit'!$R$3:$R$184,'Data check lookup table'!A36) -> 0 | G36: 141 | H36: =VLOOKUP(G36,namewithfather,2,FALSE) -> Alexandra (141): 1961– | I36: =VLOOKUP(G36,namewithfather,3,FALSE) -> 104 | J36: =VLOOKUP(I36,namewithfather,2,FALSE) -> Sir Julian (104): 1926–2018 | K36: =VLOOKUP(I36,namewithfather,3,FALSE) -> 72 | L36: =VLOOKUP(K36,namewithfather,2,FALSE) -> Charles (72): 1891–1973 | M36: =VLOOKUP(G36,'Loyd List 1-190 - Edit'!$P$3:$AN$184,25,FALSE) -> 1 | N36: =VLOOKUP(G36,'Loyd List 1-190 - Edit'!$P$3:$AGI$184,26,FALSE) -> 60 | O36: =VLOOKUP(G36,'Loyd List 1-190 - Edit'!$P$3:$AM$184,22,FALSE) -> 10 | P36: Jeremy | Q36: 02072280654 | R36: 07796178796 | S36: ambyatt@gmail.com | V36: ambyatt@gmail.com
A37: =A36+1 -> #REF! | B37: =COUNTIF('Loyd List 1-190 - Edit'!$R$3:$R$184,'Data check lookup table'!A37) -> 0 | G37: 146 | H37: =VLOOKUP(G37,namewithfather,2,FALSE) -> Charles (146): 1963– | I37: =VLOOKUP(G37,namewithfather,3,FALSE) -> 104 | J37: =VLOOKUP(I37,namewithfather,2,FALSE) -> Sir Julian (104): 1926–2018 | K37: =VLOOKUP(I37,namewithfather,3,FALSE) -> 72 | L37: =VLOOKUP(K37,namewithfather,2,FALSE) -> Charles (72): 1891–1973 | M37: =VLOOKUP(G37,'Loyd List 1-190 - Edit'!$P$3:$AN$184,25,FALSE) -> 1 | N37: =VLOOKUP(G37,'Loyd List 1-190 - Edit'!$P$3:$AGI$184,26,FALSE) -> 59 | O37: =VLOOKUP(G37,'Loyd List 1-190 - Edit'!$P$3:$AM$184,22,FALSE) -> 3 | P37: Jeremy | Q37: 01473 220435 | S37: c.loyde@icloud.com | V37: c.loyde@icloud.com
A38: =A37+1 -> #REF! | B38: =COUNTIF('Loyd List 1-190 - Edit'!$R$3:$R$184,'Data check lookup table'!A38) -> 0 | G38: 152 | H38: =VLOOKUP(G38,namewithfather,2,FALSE) -> Mary Rose (152): 1967– | I38: =VLOOKUP(G38,namewithfather,3,FALSE) -> 104 | J38: =VLOOKUP(I38,namewithfather,2,FALSE) -> Sir Julian (104): 1926–2018 | K38: =VLOOKUP(I38,namewithfather,3,FALSE) -> 72 | L38: =VLOOKUP(K38,namewithfather,2,FALSE) -> Charles (72): 1891–1973 | M38: =VLOOKUP(G38,'Loyd List 1-190 - Edit'!$P$3:$AN$184,25,FALSE) -> 1 | N38: =VLOOKUP(G38,'Loyd List 1-190 - Edit'!$P$3:$AGI$184,26,FALSE) -> 55 | O38: =VLOOKUP(G38,'Loyd List 1-190 - Edit'!$P$3:$AM$184,22,FALSE) -> 6 | P38: Jeremy | R38: 07768708288 | S38: maryrose@whitcomb.co.uk | V38: maryrose@whitcomb.co.uk
A39: =A38+1 -> #REF! | B39: =COUNTIF('Loyd List 1-190 - Edit'!$R$3:$R$184,'Data check lookup table'!A39) -> 0 | G39: 128 | H39: =VLOOKUP(G39,namewithfather,2,FALSE) -> Julie (128): 1952– | I39: =VLOOKUP(G39,namewithfather,3,FALSE) -> 98 | J39: =VLOOKUP(I39,namewithfather,2,FALSE) -> Peter (98): 1922–2022 | K39: =VLOOKUP(I39,namewithfather,3,FALSE) -> 77 | L39: =VLOOKUP(K39,namewithfather,2,FALSE) -> Wilfrid (77): 1893–1971 | M39: =VLOOKUP(G39,'Loyd List 1-190 - Edit'!$P$3:$AN$184,25,FALSE) -> 1 | N39: =VLOOKUP(G39,'Loyd List 1-190 - Edit'!$P$3:$AGI$184,26,FALSE) -> 70 | O39: =VLOOKUP(G39,'Loyd List 1-190 - Edit'!$P$3:$AM$184,22,FALSE) -> 4 | P39: Jeremy | S39: rosemaryloyd@gmail.com | V39: julieweb3004@gmail.com
A40: =A39+1 -> #REF! | B40: =COUNTIF('Loyd List 1-190 - Edit'!$R$3:$R$184,'Data check lookup table'!A40) -> 0 | G40: 134 | H40: =VLOOKUP(G40,namewithfather,2,FALSE) -> William (134): 1955– | I40: =VLOOKUP(G40,namewithfather,3,FALSE) -> 98 | J40: =VLOOKUP(I40,namewithfather,2,FALSE) -> Peter (98): 1922–2022 | K40: =VLOOKUP(I40,namewithfather,3,FALSE) -> 77 | L40: =VLOOKUP(K40,namewithfather,2,FALSE) -> Wilfrid (77): 1893–1971 | M40: =VLOOKUP(G40,'Loyd List 1-190 - Edit'!$P$3:$AN$184,25,FALSE) -> 1 | N40: =VLOOKUP(G40,'Loyd List 1-190 - Edit'!$P$3:$AGI$184,26,FALSE) -> 67 | O40: =VLOOKUP(G40,'Loyd List 1-190 - Edit'!$P$3:$AM$184,22,FALSE) -> 6 | P40: Jeremy | S40: rosemaryloyd@gmail.com | V40: williamloyd@uwclub.net
...

Sheet Book Details - NO EDIT
B1: 3 | C1: 4 | D1: 5 | E1: 2 | F1: 6 | G1: 7 | H1: 8 | I1: 11 | J1: 13 | K1: 32 | L1: 16 | M1: 12 | N1: =M1 -> 12 | O1: =N1 -> 12 | P1: =O1 -> 12 | Q1: =P1 -> 12 | R1: =Q1 -> 12 | S1: 12 | W1: =LEN(C3) -> 0 | Z1: 4 | AJ1: 12 | AK1: 7 | AX1: 28 | AY1: 13
A2: ='Loyd List 1-190 - Edit'!C1 -> Loyd # | B2: =VLOOKUP($A2,'Loyd List 1-190 - Edit'!$C$1:$AQ$184,'Book Details - NO EDIT'!B$1,FALSE) -> 1st Name | C2: =VLOOKUP($A2,'Loyd List 1-190 - Edit'!$C$1:$AQ$184,'Book Details - NO EDIT'!C$1,FALSE) -> 2nd Name | D2: =VLOOKUP($A2,'Loyd List 1-190 - Edit'!$C$1:$AQ$184,'Book Details - NO EDIT'!D$1,FALSE) -> 3rd Name | E2: =VLOOKUP($A2,'Loyd List 1-190 - Edit'!$C$1:$AQ$184,'Book Details - NO EDIT'!E$1,FALSE) -> Surname | F2: =VLOOKUP($A2,'Loyd List 1-190 - Edit'!$C$1:$AQ$184,'Book Details - NO EDIT'!F$1,FALSE) -> Known as | G2: =VLOOKUP($A2,'Loyd List 1-190 - Edit'!$C$1:$AQ$184,'Book Details - NO EDIT'!G$1,FALSE) -> Year of Birth | H2: =VLOOKUP($A2,'Loyd List 1-190 - Edit'!$C$1:$AQ$184,'Book Details - NO EDIT'!H$1,FALSE) -> Year of Death | I2: =VLOOKUP($A2,'Loyd List 1-190 - Edit'!$C$1:$AQ$184,'Book Details - NO EDIT'!I$1,FALSE) -> Dob Entered | J2: =VLOOKUP($A2,'Loyd List 1-190 - Edit'!$C$1:$AQ$184,'Book Details - NO EDIT'!J$1,FALSE) -> DoD | K2: =VLOOKUP($A2,'Loyd List 1-190 - Edit'!$C$1:$AQ$220,'Book Details - NO EDIT'!K$1,FALSE) -> Sex | L2: =VLOOKUP($A2,'Loyd List 1-190 - Edit'!$C$1:$AQ$184,'Book Details - NO EDIT'!L$1,FALSE) -> Father's Loyd # | M2: GFather's Loyd # | N2: G GFather's Loyd # | O2: GG GFather's Loyd # | P2: GGG GFather's Loyd # | Q2: GGGG GFather's Loyd # | R2: GGGGG GFather's Loyd # | S2: GGGGGG GFather's Loyd # | T2: Generation | U2: Loyd # | V2: Known as & Dates | W2: Known as & Loyd # | X2: Known as & (Dates; & Loyd #) | Y2: Birth Full Name | Z2: Father's name (Known as, Dates, Loyd #) | AA2: Lineage | AB2: Siblings (Number & List) | AC2: Children (Number and list) | AD2: Grandchildren Full List | AE2: Grandchildren (Number & List) Part 1&2 | AF2: Grandchildren (Number & List) Part 3 | AG2: Number of Grandchildren | AH2: Mother | AI2: Husband/Wife | AJ2: =IF(VLOOKUP($A2,'Loyd List 1-190 - Edit'!$C$1:$AQ$184,'Book Details - NO EDIT'!AJ$1,FALSE)="","",(VLOOKUP($A2,'Loyd List 1-190 - Edit'!$C$1:$AQ$184,'Book Details - NO EDIT'!AJ$1,FALSE))) -> DoM | AK2: Marriage Details | AL2: =VLOOKUP(A2,'Updated Bios & Spouse Details'!$A$1:$J$200,5,FALSE) -> Additional Biographical Information (Short address) | AM2: DSP? | AW2: Residency | AX2: Age | AY2: Contact
A3: ='Loyd List 1-190 - Edit'!C3 -> 1 | B3: =VLOOKUP($A3,'Loyd List 1-190 - Edit'!$C$1:$AQ$220,'Book Details - NO EDIT'!B$1,FALSE) -> William | C3: =IF(VLOOKUP($A3,'Loyd List 1-190 - Edit'!$C$1:$AQ$220,'Book Details - NO EDIT'!C$1,FALSE)="","",VLOOKUP($A3,'Loyd List 1-190 - Edit'!$C$1:$AQ$220,'Book Details - NO EDIT'!C$1,FALSE)) | D3: =IF(VLOOKUP($A3,'Loyd List 1-190 - Edit'!$C$1:$AQ$220,'Book Details - NO EDIT'!D$1,FALSE)="","",VLOOKUP($A3,'Loyd List 1-190 - Edit'!$C$1:$AQ$220,'Book Details - NO EDIT'!D$1,FALSE)) | E3: =IF(VLOOKUP($A3,'Loyd List 1-190 - Edit'!$C$1:$AQ$220,'Book Details - NO EDIT'!E$1,FALSE)="","",VLOOKUP($A3,'Loyd List 1-190 - Edit'!$C$1:$AQ$220,'Book Details - NO EDIT'!E$1,FALSE)) -> LLOYD | F3: =IF(VLOOKUP($A3,'Loyd List 1-190 - Edit'!$C$1:$AQ$220,'Book Details - NO EDIT'!F$1,FALSE)="",B3,VLOOKUP($A3,'Loyd List 1-190 - Edit'!$C$1:$AQ$220,'Book Details - NO EDIT'!F$1,FALSE)) -> William | G3: =IF(VLOOKUP($A3,'Loyd List 1-190 - Edit'!$C$1:$AQ$220,'Book Details - NO EDIT'!G$1,FALSE)="","",VALUE(VLOOKUP($A3,'Loyd List 1-190 - Edit'!$C$1:$AQ$220,'Book Details - NO EDIT'!G$1,FALSE))) -> 1729 | H3: =IF(VLOOKUP($A3,'Loyd List 1-190 - Edit'!$C$1:$AQ$220,'Book Details - NO EDIT'!H$1,FALSE)="","",VALUE(VLOOKUP($A3,'Loyd List 1-190 - Edit'!$C$1:$AQ$220,'Book Details - NO EDIT'!H$1,FALSE))) -> 1800 | I3: =IF(VLOOKUP($A3,'Loyd List 1-190 - Edit'!$C$1:$AQ$220,'Book Details - NO EDIT'!I$1,FALSE)="","",(VLOOKUP($A3,'Loyd List 1-190 - Edit'!$C$1:$AQ$220,'Book Details - NO EDIT'!I$1,FALSE))) -> 20/09/1729 | J3: =IF(VLOOKUP($A3,'Loyd List 1-190 - Edit'!$C$1:$AQ$220,'Book Details - NO EDIT'!J$1,FALSE)="","",(VLOOKUP($A3,'Loyd List 1-190 - Edit'!$C$1:$AQ$220,'Book Details - NO EDIT'!J$1,FALSE))) -> 13/05/1800 | K3: =VLOOKUP($A3,'Loyd List 1-190 - Edit'!$C$1:$AQ$220,'Book Details - NO EDIT'!K$1,FALSE) -> Boy | L3: =VLOOKUP($A3,'Loyd List 1-190 - Edit'!$C$1:$AQ$220,'Book Details - NO EDIT'!L$1,FALSE) -> 0 | M3: Thomas Lloyd (1642–1725: #-1) | N3: =IF(ISNA(VLOOKUP(M3,$A$3:$L$220,N$1,FALSE)),"",(VLOOKUP(M3,$A$3:$L$220,N$1,FALSE))) | O3: =IF(ISNA(VLOOKUP(N3,$A$3:$L$220,O$1,FALSE)),"",(VLOOKUP(N3,$A$3:$L$220,O$1,FALSE))) | P3: =IF(ISNA(VLOOKUP(O3,$A$3:$L$220,P$1,FALSE)),"",(VLOOKUP(O3,$A$3:$L$220,P$1,FALSE))) | Q3: =IF(ISNA(VLOOKUP(P3,$A$3:$L$220,Q$1,FALSE)),"",(VLOOKUP(P3,$A$3:$L$220,Q$1,FALSE))) | R3: =IF(ISNA(VLOOKUP(Q3,$A$3:$L$220,R$1,FALSE)),"",(VLOOKUP(Q3,$A$3:$L$220,R$1,FALSE))) | S3: =IF(ISNA(VLOOKUP(R3,$A$3:$L$220,S$1,FALSE)),"",(VLOOKUP(R3,$A$3:$L$220,S$1,FALSE))) | T3: =IF(L3=1,1,IF(M3=1,2,IF(N3=1,3,IF(O3=1,4,IF(P3=1,5,IF(Q3=1,6,IF(R3=1,7,IF(S3=1,8,0)))))))) -> 0 | U3: =A3 -> 1 | V3: =_xlfn.CONCAT(F3," (",G3,"–",H3,")") -> William (1729–1800) | W3: =_xlfn.CONCAT(F3," (#",A3,")") -> William (#1) | X3: =_xlfn.CONCAT(F3," (",G3,"–",H3,": #",A3,")") -> William (1729–1800: #1) | Y3: =_xlfn.CONCAT(B3," ",IF(C3="",E3,_xlfn.CONCAT(C3," ",IF(D3="",E3,_xlfn.CONCAT(D3," ",E3))))) -> William LLOYD | Z3: Lewis Lloyd (c1690–1758: #0) | AA3: Lewis Lloyd (c1690 –1758; #0) Thomas Lloyd (1642–1725: #-1) | AB3: =VLOOKUP(U3,'Siblings of those BORN Loyd'!$A$2:$G$230,7,FALSE) -> 5 – Gwenllian Lloyd (1719 - c1800) Edward Lloyd (1721 - 1751) Elizabeth Lloyd (1726 - 1777) Jane Lloyd (recorded living in 1766) Catherine Lloyd (recorded living in 1766) | AC3: =IF(ISNA(IF(K3="Boy",VLOOKUP(A3,'Siblings of those BORN Loyd'!$AP$3:$AQ$70,2,FALSE),VLOOKUP(A3,'Children of Female Loyds'!$AR$5:$AT$60,3,FALSE))),AM3,IF(K3="Boy",VLOOKUP(A3,'Siblings of those BORN Loyd'!$AP$3:$AQ$70,2,FALSE),VLOOKUP(A3,'Children of Female Loyds'!$AR$5:$AT$60,3,FALSE))) -> 7 - Jane (1765–1832: #2); Lewis LOYD (1768–1858: #3); William (1770–1828: #4); Catherine (1772–1798: #5); Thomas (1775–1853: #6); Gwenllian (1777–1779: #7); Edward (1780–1863: #8) | AD3: =IF(AE3="d.s.p",_xlfn.CONCAT(AE3,"."),IF(AG3=0,"-",_xlfn.CONCAT(AG3," - ",AE3," ",AF3))) -> 19 - Samuel (1796–1883: #9); William (1809–1879: #10); Sarah (1810–1858: #11); Eliza (1810–1861: #12); Lewis (1811–1891: #13); Thomas (1812–1857: #14); Annie (1813–1834: #15); Maria (1814–1900: #16); Edward (1815–1815: #17); Kate (1815–1905: #18); Hannah (1817–1907: #19); John (1817–1818: #20); Lewis (1819–1841: #21); Edward (1820–1890: #22) ;William (1821–1885: #23); Fanny (1824–1856: #24) Lewis DAVIES or DANIEL (Unknown - Unknown: #2a) Ann DAVIES or DANIEL (Unknown - Unknown: #2b) William DAVIES or DANIEL (1800 - 1832: #2c) | AE3: =IF(ISNA(IF(K3="Boy",VLOOKUP(A3,'Grandchildren of Male Loyds'!$AQ$3:$AS$51,3,FALSE),VLOOKUP(A3,'Grandchildren of Female Loyds'!$AX$5:$AZ$63,3,FALSE))),AM3,IF(K3="Boy",VLOOKUP(A3,'Grandchildren of Male Loyds'!$AQ$3:$AS$51,3,FALSE),VLOOKUP(A3,'Grandchildren of Female Loyds'!$AX$5:$AZ$63,3,FALSE))) -> Samuel (1796–1883: #9); William (1809–1879: #10); Sarah (1810–1858: #11); Eliza (1810–1861: #12); Lewis (1811–1891: #13); Thomas (1812–1857: #14); Annie (1813–1834: #15); Maria (1814–1900: #16); Edward (1815–1815: #17); Kate (1815–1905: #18); Hannah (1817–1907: #19); John (1817–1818: #20); Lewis (1819–1841: #21); Edward (1820–1890: #22) ;William (1821–1885: #23); Fanny (1824–1856: #24) | AF3: =IF(ISNA(VLOOKUP(A3,'Grandchildren Loyd Daughters'!$BD$5:$BF$50,4,FALSE)),"",VLOOKUP(A3,'Grandchildren Loyd Daughters'!$BD$5:$BF$50,3,FALSE)) -> Lewis DAVIES or DANIEL (Unknown - Unknown: #2a) Ann DAVIES or DANIEL (Unknown - Unknown: #2b) William DAVIES or DANIEL (1800 - 1832: #2c) | AG3: =IF(ISNA(VLOOKUP(A3,'Grandchildren of Male Loyds'!$AQ$3:$AR$60,2,FALSE)),0,VLOOKUP(A3,'Grandchildren of Male Loyds'!$AQ$3:$AR$60,2,FALSE))+IF(ISNA(VLOOKUP(A3,'Grandchildren of Female Loyds'!$AX$5:$AY$50,2,FALSE)),0,VLOOKUP(A3,'Grandchildren of Female Loyds'!$AX$5:$AY$50,2,FALSE))+IF(ISNA(VLOOKUP(A3,'Grandchildren Loyd Daughters'!$BD$5:$BE$50,2,FALSE)),0,VLOOKUP(A3,'Grandchildren Loyd Daughters'!$BD$5:$BE$50,2,FALSE)) -> 19 | AH3: =VLOOKUP($U3,'Loyd List 1-190 - Edit'!$P$3:$AJ$220,21,FALSE) -> Jane (b. , d. 26/11/1761) | AI3: =VLOOKUP(A3,'Updated Bios & Spouse Details'!$A$1:$J$200,7,FALSE) -> Anne WILLIAM (b. 1738 , d. 24 May 1801) | AJ3: =IF(VLOOKUP($A3,'Loyd List 1-190 - Edit'!$C$1:$AQ$220,'Book Details - NO EDIT'!AJ$1,FALSE)="","",(VLOOKUP($A3,'Loyd List 1-190 - Edit'!$C$1:$AQ$220,'Book Details - NO EDIT'!AJ$1,FALSE))) -> 03/01/1765 | AK3: =VLOOKUP(A3,'Updated Bios & Spouse Details'!$A$1:$J$200,8,FALSE) -> Married Anne at Llanfair-ar-y-bryn, Llandovery, daughter of John WILLIAM of Llanfair-ar-y-bryn, Llandovery. Anne buried 28 May 1801 at Cilycwm. | AL3: =VLOOKUP(A3,'Updated Bios & Spouse Details'!$A$1:$J$200,5,FALSE) -> Yeoman of Cwm-y-to fach and afterwards (1795) of Court Henry [1] in the parish of Cilycwm, Carmarthenshire. 3rd and youngest son of Lewis LLOYD (c.1690–1758: #0) [2] of Cwm-y-to fach in the parish of Llanwrda. Baptised 20 Sep 1729 at Llanwrda. Died 13 May 1800. Buried 16 May 1800 at Cilycwm. Issue: 3 daughters, 4 sons. Will dated 8 July 1799, proved 24 May 1800 at Carmarthen. Original in National Library of Wales, Aberystwyth. Churchwarden Llanwrda 1766 and 1791 Tombstone in Cilycwm Churchyard. Issue: 4 sons, 3 daughters. Footnote: [1] Court Henry (spelt CWRT HENRY on first Ordnance Survey maps printed in 1865) was sold by Lord Overstone in 1881 for £1,000. [2] Lewis Lloyd died 24 Aug 1758. Buried 25 or 26 Aug 1758 at Llanwrda. Lewis' will dated 8 Jan 1757, proved 10 Jul 1760. Total assets £12-3 shillings. Original in the National Library of Wales, Aberystwyth (Testators’ Wills index St David’s Diocese). | AM3: =IF(AND(LEN(H3)>0,ISNA(IF(K3="Boy",VLOOKUP(A3,'Siblings of those BORN Loyd'!$AP$3:$AQ$70,2,FALSE),VLOOKUP(A3,'Children of Female Loyds'!$AR$5:$AS$60,2,FALSE)))),"d.s.p","") | AW3: =VLOOKUP(A3,'Updated Bios & Spouse Details'!$A$1:$J$193,6,FALSE) -> Wales | AX3: =VLOOKUP($A3,'Loyd List 1-190 - Edit'!$P$2:$AQ$220,AX$1,FALSE) -> 1 | AY3: =IF(ISNA(VLOOKUP(A3,'Data check lookup table'!$G$2:$V$73,13,FALSE))," - ",VLOOKUP(A3,'Data check lookup table'!$G$2:$V$73,13,FALSE)) -> - | AZ3: =TEXT(J3,"dd/mm/yyyy") -> 13/05/1800 | BI3: 13/05/1800
A4: ='Loyd List 1-190 - Edit'!C4 -> 2 | B4: =VLOOKUP($A4,'Loyd List 1-190 - Edit'!$C$1:$AQ$220,'Book Details - NO EDIT'!B$1,FALSE) -> Jane | C4: =IF(VLOOKUP($A4,'Loyd List 1-190 - Edit'!$C$1:$AQ$220,'Book Details - NO EDIT'!C$1,FALSE)="","",VLOOKUP($A4,'Loyd List 1-190 - Edit'!$C$1:$AQ$220,'Book Details - NO EDIT'!C$1,FALSE)) | D4: =IF(VLOOKUP($A4,'Loyd List 1-190 - Edit'!$C$1:$AQ$220,'Book Details - NO EDIT'!D$1,FALSE)="","",VLOOKUP($A4,'Loyd List 1-190 - Edit'!$C$1:$AQ$220,'Book Details - NO EDIT'!D$1,FALSE)) | E4: =IF(VLOOKUP($A4,'Loyd List 1-190 - Edit'!$C$1:$AQ$220,'Book Details - NO EDIT'!E$1,FALSE)="","",VLOOKUP($A4,'Loyd List 1-190 - Edit'!$C$1:$AQ$220,'Book Details - NO EDIT'!E$1,FALSE)) -> LLOYD | F4: =IF(VLOOKUP($A4,'Loyd List 1-190 - Edit'!$C$1:$AQ$220,'Book Details - NO EDIT'!F$1,FALSE)="",B4,VLOOKUP($A4,'Loyd List 1-190 - Edit'!$C$1:$AQ$220,'Book Details - NO EDIT'!F$1,FALSE)) -> Jane | G4: =IF(VLOOKUP($A4,'Loyd List 1-190 - Edit'!$C$1:$AQ$220,'Book Details - NO EDIT'!G$1,FALSE)="","",VALUE(VLOOKUP($A4,'Loyd List 1-190 - Edit'!$C$1:$AQ$220,'Book Details - NO EDIT'!G$1,FALSE))) -> 1765 | H4: =IF(VLOOKUP($A4,'Loyd List 1-190 - Edit'!$C$1:$AQ$220,'Book Details - NO EDIT'!H$1,FALSE)="","",VALUE(VLOOKUP($A4,'Loyd List 1-190 - Edit'!$C$1:$AQ$220,'Book Details - NO EDIT'!H$1,FALSE))) -> 1832 | I4: =IF(VLOOKUP($A4,'Loyd List 1-190 - Edit'!$C$1:$AQ$220,'Book Details - NO EDIT'!I$1,FALSE)="","",(VLOOKUP($A4,'Loyd List 1-190 - Edit'!$C$1:$AQ$220,'Book Details - NO EDIT'!I$1,FALSE))) -> 29/10/1765 | J4: =IF(VLOOKUP($A4,'Loyd List 1-190 - Edit'!$C$1:$AQ$220,'Book Details - NO EDIT'!J$1,FALSE)="","",(VLOOKUP($A4,'Loyd List 1-190 - Edit'!$C$1:$AQ$220,'Book Details - NO EDIT'!J$1,FALSE))) -> 11/05/1832 | K4: =VLOOKUP($A4,'Loyd List 1-190 - Edit'!$C$1:$AQ$220,'Book Details - NO EDIT'!K$1,FALSE) -> Girl | L4: =VLOOKUP($A4,'Loyd List 1-190 - Edit'!$C$1:$AQ$220,'Book Details - NO EDIT'!L$1,FALSE) -> 1 | M4: =IF(ISNA(VLOOKUP(L4,$A$3:$L$220,M$1,FALSE)),"",(VLOOKUP(L4,$A$3:$L$220,M$1,FALSE))) -> 0 | N4: =IF(ISNA(VLOOKUP(M4,$A$3:$L$220,N$1,FALSE)),"",(VLOOKUP(M4,$A$3:$L$220,N$1,FALSE))) | O4: =IF(ISNA(VLOOKUP(N4,$A$3:$L$220,O$1,FALSE)),"",(VLOOKUP(N4,$A$3:$L$220,O$1,FALSE))) | P4: =IF(ISNA(VLOOKUP(O4,$A$3:$L$220,P$1,FALSE)),"",(VLOOKUP(O4,$A$3:$L$220,P$1,FALSE))) | Q4: =IF(ISNA(VLOOKUP(P4,$A$3:$L$220,Q$1,FALSE)),"",(VLOOKUP(P4,$A$3:$L$220,Q$1,FALSE))) | R4: =IF(ISNA(VLOOKUP(Q4,$A$3:$L$220,R$1,FALSE)),"",(VLOOKUP(Q4,$A$3:$L$220,R$1,FALSE))) | S4: =IF(ISNA(VLOOKUP(R4,$A$3:$L$220,S$1,FALSE)),"",(VLOOKUP(R4,$A$3:$L$220,S$1,FALSE))) | T4: =IF(L4=1,1,IF(M4=1,2,IF(N4=1,3,IF(O4=1,4,IF(P4=1,5,IF(Q4=1,6,IF(R4=1,7,IF(S4=1,8,0)))))))) -> 1 | U4: =A4 -> 2 | V4: =_xlfn.CONCAT(F4," (",G4,"–",H4,")") -> Jane (1765–1832) | W4: =_xlfn.CONCAT(F4," (#",A4,")") -> Jane (#2) | X4: =_xlfn.CONCAT(F4," (",G4,"–",H4,": #",A4,")") -> Jane (1765–1832: #2) | Y4: =_xlfn.CONCAT(B4," ",IF(C4="",E4,_xlfn.CONCAT(C4," ",IF(D4="",E4,_xlfn.CONCAT(D4," ",E4))))) -> Jane LLOYD | Z4: =VLOOKUP(L4,$U$2:$X$230,Z$1,FALSE) -> William (1729–1800: #1) | AA4: =_xlfn.CONCAT(AN4," ",AO4," ",AP4," ",AQ4," ",AR4," ",AS4," ",AT4," ",AU4) -> William (1729–1800: #1) | AB4: =VLOOKUP(U4,'Siblings of those BORN Loyd'!$A$2:$G$230,7,FALSE) -> 6 – Lewis LOYD (1768–1858: #3) William (1770–1828: #4) Catherine (1772–1798: #5) Thomas (1775–1853: #6) Gwenllian (1777–1779: #7) Edward (1780–1863: #8) | AC4: =IF(ISNA(IF(K4="Boy",VLOOKUP(A4,'Siblings of those BORN Loyd'!$AP$3:$AQ$70,2,FALSE),VLOOKUP(A4,'Children of Female Loyds'!$AR$5:$AT$60,3,FALSE))),AM4,IF(K4="Boy",VLOOKUP(A4,'Siblings of those BORN Loyd'!$AP$3:$AQ$70,2,FALSE),VLOOKUP(A4,'Children of Female Loyds'!$AR$5:$AT$60,3,FALSE))) -> 3 - Lewis DAVIES or DANIEL (Unknown - Unknown: #2a) Ann DAVIES or DANIEL (Unknown - Unknown: #2b) William DAVIES or DANIEL (1800 - 1832: #2c) | AD4: =IF(AE4="d.s.p",_xlfn.CONCAT(AE4,"."),IF(AG4=0,"-",_xlfn.CONCAT(AG4," - ",AE4," ",AF4))) -> 2 - William DAVIES (Date unknown -1908: #2aa) Catherine DAVIES (1829 -1866: #2ca) | AE4: =IF(ISNA(IF(K4="Boy",VLOOKUP(A4,'Grandchildren of Male Loyds'!$AQ$3:$AS$51,3,FALSE),VLOOKUP(A4,'Grandchildren of Female Loyds'!$AX$5:$AZ$63,3,FALSE))),AM4,IF(K4="Boy",VLOOKUP(A4,'Grandchildren of Male Loyds'!$AQ$3:$AS$51,3,FALSE),VLOOKUP(A4,'Grandchildren of Female Loyds'!$AX$5:$AZ$63,3,FALSE))) -> William DAVIES (Date unknown -1908: #2aa) Catherine DAVIES (1829 -1866: #2ca) | AF4: =IF(ISNA(VLOOKUP(A4,'Grandchildren Loyd Daughters'!$BD$5:$BF$50,4,FALSE)),"",VLOOKUP(A4,'Grandchildren Loyd Daughters'!$BD$5:$BF$50,3,FALSE)) | AG4: =IF(ISNA(VLOOKUP(A4,'Grandchildren of Male Loyds'!$AQ$3:$AR$60,2,FALSE)),0,VLOOKUP(A4,'Grandchildren of Male Loyds'!$AQ$3:$AR$60,2,FALSE))+IF(ISNA(VLOOKUP(A4,'Grandchildren of Female Loyds'!$AX$5:$AY$50,2,FALSE)),0,VLOOKUP(A4,'Grandchildren of Female Loyds'!$AX$5:$AY$50,2,FALSE))+IF(ISNA(VLOOKUP(A4,'Grandchildren Loyd Daughters'!$BD$5:$BE$50,2,FALSE)),0,VLOOKUP(A4,'Grandchildren Loyd Daughters'!$BD$5:$BE$50,2,FALSE)) -> 2 | AH4: =VLOOKUP($U4,'Loyd List 1-190 - Edit'!$P$3:$AJ$220,21,FALSE) -> Anne WILLIAM (b. 1738, d. 24 May 1801) | AI4: =VLOOKUP(A4,'Updated Bios & Spouse Details'!$A$1:$J$200,7,FALSE) -> Lewis DANIEL or DAVIES | AJ4: =IF(VLOOKUP($A4,'Loyd List 1-190 - Edit'!$C$1:$AQ$220,'Book Details - NO EDIT'!AJ$1,FALSE)="","",(VLOOKUP($A4,'Loyd List 1-190 - Edit'!$C$1:$AQ$220,'Book Details - NO EDIT'!AJ$1,FALSE))) -> 03/02/1795 | AK4: =VLOOKUP(A4,'Updated Bios & Spouse Details'!$A$1:$J$200,8,FALSE) -> Married at Llanwrda,Lewis of Caio, Carmarthenshire, Yeoman, afterwards of Court Henry after her father’s death in 1800. | AL4: =VLOOKUP(A4,'Updated Bios & Spouse Details'!$A$1:$J$200,5,FALSE) -> Jane was the eldest daughter of William LLOYD (1729–1800: #1) of Court Henry, Cilycwm, Carmarthenshire. b. 29 Oct 1765, baptised 4 or 9 Nov 1765 at Llanwrda. Died 11 May 1832, buried at Cilycwm. Issue: 2 sons 1 daughter. | AM4: =IF(AND(LEN(H4)>0,ISNA(IF(K4="Boy",VLOOKUP(A4,'Siblings of those BORN Loyd'!$AP$3:$AQ$70,2,FALSE),VLOOKUP(A4,'Children of Female Loyds'!$AR$5:$AS$60,2,FALSE)))),"d.s.p","") | AN4: =(IF(OR(L4=0,LEN(L4)=0),"",_xlfn.CONCAT(VLOOKUP(L4,$U$3:$X$230,4,FALSE)))) -> William (1729–1800: #1) | AO4: =(IF(OR(M4=0,LEN(M4)=0),"",_xlfn.CONCAT(VLOOKUP(M4,$U$3:$X$230,4,FALSE)))) | AP4: =(IF(OR(N4=0,LEN(N4)=0),"",_xlfn.CONCAT(VLOOKUP(N4,$U$3:$X$230,4,FALSE)))) | AQ4: =(IF(OR(O4=0,LEN(O4)=0),"",_xlfn.CONCAT(VLOOKUP(O4,$U$3:$X$230,4,FALSE)))) | AR4: =(IF(OR(P4=0,LEN(P4)=0),"",_xlfn.CONCAT(VLOOKUP(P4,$U$3:$X$230,4,FALSE)))) | AS4: =(IF(OR(Q4=0,LEN(Q4)=0),"",_xlfn.CONCAT(VLOOKUP(Q4,$U$3:$X$230,4,FALSE)))) | AT4: =(IF(OR(R4=0,LEN(R4)=0),"",_xlfn.CONCAT(VLOOKUP(R4,$U$3:$X$230,4,FALSE)))) | AU4: =(IF(OR(S4=0,LEN(S4)=0),"",_xlfn.CONCAT(VLOOKUP(S4,$U$3:$X$230,4,FALSE)))) | AW4: =VLOOKUP(A4,'Updated Bios & Spouse Details'!$A$1:$J$193,6,FALSE) -> Wales | AX4: =VLOOKUP($A4,'Loyd List 1-190 - Edit'!$P$2:$AQ$220,AX$1,FALSE) -> 2 | AY4: =IF(ISNA(VLOOKUP(A4,'Data check lookup table'!$G$2:$V$73,13,FALSE))," - ",VLOOKUP(A4,'Data check lookup table'!$G$2:$V$73,13,FALSE)) -> - | AZ4: =TEXT(J4,"dd/mm/yyyy") -> 11/05/1832 | BA4: =(IF(OR(Q4=0,LEN(Q4)=0),"",_xlfn.CONCAT(", ",VLOOKUP(Q4,$U$3:$X$230,4,FALSE)))) | BB4: =(IF(OR(R4=0,LEN(R4)=0),"",_xlfn.CONCAT("; ",VLOOKUP(R4,$U$3:$X$230,4,FALSE)))) | BI4: 11/05/1832
A5: ='Loyd List 1-190 - Edit'!C5 -> 3 | B5: =VLOOKUP($A5,'Loyd List 1-190 - Edit'!$C$1:$AQ$220,'Book Details - NO EDIT'!B$1,FALSE) -> Lewis | C5: =IF(VLOOKUP($A5,'Loyd List 1-190 - Edit'!$C$1:$AQ$220,'Book Details - NO EDIT'!C$1,FALSE)="","",VLOOKUP($A5,'Loyd List 1-190 - Edit'!$C$1:$AQ$220,'Book Details - NO EDIT'!C$1,FALSE)) | D5: =IF(VLOOKUP($A5,'Loyd List 1-190 - Edit'!$C$1:$AQ$220,'Book Details - NO EDIT'!D$1,FALSE)="","",VLOOKUP($A5,'Loyd List 1-190 - Edit'!$C$1:$AQ$220,'Book Details - NO EDIT'!D$1,FALSE)) | E5: =IF(VLOOKUP($A5,'Loyd List 1-190 - Edit'!$C$1:$AQ$220,'Book Details - NO EDIT'!E$1,FALSE)="","",VLOOKUP($A5,'Loyd List 1-190 - Edit'!$C$1:$AQ$220,'Book Details - NO EDIT'!E$1,FALSE)) -> LOYD | F5: =IF(VLOOKUP($A5,'Loyd List 1-190 - Edit'!$C$1:$AQ$220,'Book Details - NO EDIT'!F$1,FALSE)="",B5,VLOOKUP($A5,'Loyd List 1-190 - Edit'!$C$1:$AQ$220,'Book Details - NO EDIT'!F$1,FALSE)) -> Lewis LOYD | G5: =IF(VLOOKUP($A5,'Loyd List 1-190 - Edit'!$C$1:$AQ$220,'Book Details - NO EDIT'!G$1,FALSE)="","",VALUE(VLOOKUP($A5,'Loyd List 1-190 - Edit'!$C$1:$AQ$220,'Book Details - NO EDIT'!G$1,FALSE))) -> 1768 | H5: =IF(VLOOKUP($A5,'Loyd List 1-190 - Edit'!$C$1:$AQ$220,'Book Details - NO EDIT'!H$1,FALSE)="","",VALUE(VLOOKUP($A5,'Loyd List 1-190 - Edit'!$C$1:$AQ$220,'Book Details - NO EDIT'!H$1,FALSE))) -> 1858 | I5: =IF(VLOOKUP($A5,'Loyd List 1-190 - Edit'!$C$1:$AQ$220,'Book Details - NO EDIT'!I$1,FALSE)="","",(VLOOKUP($A5,'Loyd List 1-190 - Edit'!$C$1:$AQ$220,'Book Details - NO EDIT'!I$1,FALSE))) -> 01/01/1768 | J5: =IF(VLOOKUP($A5,'Loyd List 1-190 - Edit'!$C$1:$AQ$220,'Book Details - NO EDIT'!J$1,FALSE)="","",(VLOOKUP($A5,'Loyd List 1-190 - Edit'!$C$1:$AQ$220,'Book Details - NO EDIT'!J$1,FALSE))) -> 13/05/1858 | K5: =VLOOKUP($A5,'Loyd List 1-190 - Edit'!$C$1:$AQ$220,'Book Details - NO EDIT'!K$1,FALSE) -> Boy | L5: =VLOOKUP($A5,'Loyd List 1-190 - Edit'!$C$1:$AQ$220,'Book Details - NO EDIT'!L$1,FALSE) -> 1 | M5: =IF(ISNA(VLOOKUP(L5,$A$3:$L$220,M$1,FALSE)),"",(VLOOKUP(L5,$A$3:$L$220,M$1,FALSE))) -> 0 | N5: =IF(ISNA(VLOOKUP(M5,$A$3:$L$220,N$1,FALSE)),"",(VLOOKUP(M5,$A$3:$L$220,N$1,FALSE))) | O5: =IF(ISNA(VLOOKUP(N5,$A$3:$L$220,O$1,FALSE)),"",(VLOOKUP(N5,$A$3:$L$220,O$1,FALSE))) | P5: =IF(ISNA(VLOOKUP(O5,$A$3:$L$220,P$1,FALSE)),"",(VLOOKUP(O5,$A$3:$L$220,P$1,FALSE))) | Q5: =IF(ISNA(VLOOKUP(P5,$A$3:$L$220,Q$1,FALSE)),"",(VLOOKUP(P5,$A$3:$L$220,Q$1,FALSE))) | R5: =IF(ISNA(VLOOKUP(Q5,$A$3:$L$220,R$1,FALSE)),"",(VLOOKUP(Q5,$A$3:$L$220,R$1,FALSE))) | S5: =IF(ISNA(VLOOKUP(R5,$A$3:$L$220,S$1,FALSE)),"",(VLOOKUP(R5,$A$3:$L$220,S$1,FALSE))) | T5: =IF(L5=1,1,IF(M5=1,2,IF(N5=1,3,IF(O5=1,4,IF(P5=1,5,IF(Q5=1,6,IF(R5=1,7,IF(S5=1,8,0)))))))) -> 1 | U5: =A5 -> 3 | V5: =_xlfn.CONCAT(F5," (",G5,"–",H5,")") -> Lewis LOYD (1768–1858) | W5: =_xlfn.CONCAT(F5," (#",A5,")") -> Lewis LOYD (#3) | X5: =_xlfn.CONCAT(F5," (",G5,"–",H5,": #",A5,")") -> Lewis LOYD (1768–1858: #3) | Y5: =_xlfn.CONCAT(B5," ",IF(C5="",E5,_xlfn.CONCAT(C5," ",IF(D5="",E5,_xlfn.CONCAT(D5," ",E5))))) -> Lewis LOYD | Z5: =VLOOKUP(L5,$U$2:$X$230,Z$1,FALSE) -> William (1729–1800: #1) | AA5: =_xlfn.CONCAT(AN5," ",AO5," ",AP5," ",AQ5," ",AR5," ",AS5," ",AT5," ",AU5) -> William (1729–1800: #1) | AB5: =VLOOKUP(U5,'Siblings of those BORN Loyd'!$A$2:$G$230,7,FALSE) -> 6 – Jane (1765–1832: #2) William (1770–1828: #4) Catherine (1772–1798: #5) Thomas (1775–1853: #6) Gwenllian (1777–1779: #7) Edward (1780–1863: #8) | AC5: =IF(ISNA(IF(K5="Boy",VLOOKUP(A5,'Siblings of those BORN Loyd'!$AP$3:$AQ$70,2,FALSE),VLOOKUP(A5,'Children of Female Loyds'!$AR$5:$AT$60,3,FALSE))),AM5,IF(K5="Boy",VLOOKUP(A5,'Siblings of those BORN Loyd'!$AP$3:$AQ$70,2,FALSE),VLOOKUP(A5,'Children of Female Loyds'!$AR$5:$AT$60,3,FALSE))) -> 1 - Samuel (1796–1883: #9) | AD5: =IF(AE5="d.s.p",_xlfn.CONCAT(AE5,"."),IF(AG5=0,"-",_xlfn.CONCAT(AG5," - ",AE5," ",AF5))) -> 2 - Henry (1832–1833: #25); The Hon Harriet (1837–1920: #26) | AE5: =IF(ISNA(IF(K5="Boy",VLOOKUP(A5,'Grandchildren of Male Loyds'!$AQ$3:$AS$51,3,FALSE),VLOOKUP(A5,'Grandchildren of Female Loyds'!$AX$5:$AZ$63,3,FALSE))),AM5,IF(K5="Boy",VLOOKUP(A5,'Grandchildren of Male Loyds'!$AQ$3:$AS$51,3,FALSE),VLOOKUP(A5,'Grandchildren of Female Loyds'!$AX$5:$AZ$63,3,FALSE))) -> Henry (1832–1833: #25); The Hon Harriet (1837–1920: #26) | AF5: =IF(ISNA(VLOOKUP(A5,'Grandchildren Loyd Daughters'!$BD$5:$BF$50,4,FALSE)),"",VLOOKUP(A5,'Grandchildren Loyd Daughters'!$BD$5:$BF$50,3,FALSE)) | AG5: =IF(ISNA(VLOOKUP(A5,'Grandchildren of Male Loyds'!$AQ$3:$AR$60,2,FALSE)),0,VLOOKUP(A5,'Grandchildren of Male Loyds'!$AQ$3:$AR$60,2,FALSE))+IF(ISNA(VLOOKUP(A5,'Grandchildren of Female Loyds'!$AX$5:$AY$50,2,FALSE)),0,VLOOKUP(A5,'Grandchildren of Female Loyds'!$AX$5:$AY$50,2,FALSE))+IF(ISNA(VLOOKUP(A5,'Grandchildren Loyd Daughters'!$BD$5:$BE$50,2,FALSE)),0,VLOOKUP(A5,'Grandchildren Loyd Daughters'!$BD$5:$BE$50,2,FALSE)) -> 2 | AH5: =VLOOKUP($U5,'Loyd List 1-190 - Edit'!$P$3:$AJ$220,21,FALSE) -> Anne WILLIAM (b. 1738, d. 24 May 1801) | AI5: =VLOOKUP(A5,'Updated Bios & Spouse Details'!$A$1:$J$200,7,FALSE) -> (1) Sarah JONES 7 (b. 9 Sep 1759, d. 1 Oct 1821). | AJ5: =IF(VLOOKUP($A5,'Loyd List 1-190 - Edit'!$C$1:$AQ$220,'Book Details - NO EDIT'!AJ$1,FALSE)="","",(VLOOKUP($A5,'Loyd List 1-190 - Edit'!$C$1:$AQ$220,'Book Details - NO EDIT'!AJ$1,FALSE))) -> 11/11/1793 | AK5: =VLOOKUP(A5,'Updated Bios & Spouse Details'!$A$1:$J$200,8,FALSE) -> (1) 11 Nov 1793 Sarah (b. 9 Sep 1759, d. 1 Oct 1821) at Broughton New Hall, daughter of John JONES (1713-75) banker and Tea dealer of Manchester and founder of the King Street Bank. Sarah buried at Cross Street Chapel, Manchester. (2) Married Mrs. Mary CHAMPION (d. 1 Feb 1835) on 21 Jan 1823. | AL5: =VLOOKUP(A5,'Updated Bios & Spouse Details'!$A$1:$J$200,5,FALSE) -> Lewis lived at 43 Lothbury, London and of Overstone Park, Northamptonshire. Eldest son of William LLOYD (1729–1800: #1) of Court Henry, Cilycwm, Carmarthenshire. Born 1 Jan 1768, baptised 5 Jan 1768 at Llanwrda. Educated at Mr. David PRICE’s school [5] at Llanycrwys near Lampeter and at the Presbyterian Academy of Carmarthen, Swansea (1785-89). Rode to Manchester in September 1789. Entered Manchester Unitarian College. Appointed Tutor in Belle Letters at Manchester 1790-92. Became Supply Preacher at Dob Lane Chapel, Failsworth, Manchester [6]. Also preached at Blackley where he met his future wife, Sarah Jones. Lewis joined the Bank before relocating to the London branch as partner with Daniel, Jones, Barker, Loyd & Co. 1793. Jones, Loyd, Hulme & Co. 1798. Jones, Loyd & Co. 1808. Retired from Bank 1844. Changed the family name to LOYD about 1795. Obtained the grant of arms 10 Apr 1835 on his appointment as High Sheriff of Northamptonshire, and registered it at the College of Arms in the name of his father in order to include his brothers and their descendants. Died 13 May 1858 at Overstone, buried at Overstone. Will dated 21 Nov 1843. Estate left to Lord OVERSTONE:- Land £1,172,091, Securities £701,102, Personal effects £5,639. Issue: (1st wife) 1 son (who later became Lord OVERSTONE). Portrait by Eden Upton EDDIS in possession of Christopher Lewis LOYD (1923–2013: #100). Able and far-sighted to a degree, this extraordinary man (Lewis LOYD), of whom unfortunately not very much is known, was endowed with a biting wit; when, in 1828, Frys & Chapman - Joseph Fry was the husband of the great reformer Mrs Elizabeth Fry (nee Gurney) - had to close its doors, he told a Quaker client who had been wise enough previously to withdraw his money and to entrust it to a “more sophisticated house”, “Thou wer’t right, friend: it is wiser to place thy money with a rich sinner than with a poor saint.” Overstone Library, Reading University. Footnotes: [5] When David PRICE’s youngest son, Lewis, died in London, his old pupil, Lewis LOYD, was at his bedside. [6] “At the time in question.....to get to Dob Lane Chapel from the College was quite a journey. Lewis Loyd made his way to it Sunday by Sunday, upon the identical little white pony which had carried him from Carmarthenshire to Manchester, trotting, not along a wearily-extended street, but between hedgerows and pastures. It was a wild and rebellious little animal, and until the time for its master’s return to Dawson Street in the evening, was turned into a meadow belonging to a Mr Barrett, a leading man at Dob Lane Chapel, and at whose house Lewis Loyd was usually the welcome guest. Another leading member of the Dob Lane congregation was a Mr Samuel Taylor, a merchant in Princess Street, whose residence was at Moston. It was from this old gentleman, if tradition be trustworthy, that Lewis Loyd received his first lessons in the inestimable and immortal science of how to get rich. Mr Taylor seems to have discovered very early that Lewis had a remarkable gift for figures and accounts. He certainly led him on to a realization of his native powers. Probably it was Mr Taylor who, after service one fine morning, presented the young preacher with a bank note in acknowledgment of the excellent way in which he acquitted himself in the pulpit. Money in those days was a scarce article with the budding Croesus. His salary, it is said, was £40 a year. He thanked the donor cordially, and added that on the same terms he would gladly pray for him every Sunday of the year. Whether it was at this particular period, or a trifle later, that Lewis Loyd was engaged in writing his tract upon Original Sin, there is no evidence to show. (The tract in question was one of a series of ‘Letters to the Inhabitants of Wigan occasioned by the Rev Mr Tawell’s Discourse on the Divinity of Jesus Christ, 1791’. The volume, which is rare, consists of one hundred and sixty pages (size 12mo), twelve of which are Lewis Loyd’s.)” - Grindon p 58-59. Roddy SALE (#97d), in 2021, has portrait of Samuel & William Jones (1746 – 1819) of Greenhill and William Jones (1757 – 1821) who owned Wolvey in Warwickshire (left to Lord Overstone). | AM5: =IF(AND(LEN(H5)>0,ISNA(IF(K5="Boy",VLOOKUP(A5,'Siblings of those BORN Loyd'!$AP$3:$AQ$70,2,FALSE),VLOOKUP(A5,'Children of Female Loyds'!$AR$5:$AS$60,2,FALSE)))),"d.s.p","") | AN5: =(IF(OR(L5=0,LEN(L5)=0),"",_xlfn.CONCAT(VLOOKUP(L5,$U$3:$X$230,4,FALSE)))) -> William (1729–1800: #1) | AO5: =(IF(OR(M5=0,LEN(M5)=0),"",_xlfn.CONCAT(VLOOKUP(M5,$U$3:$X$230,4,FALSE)))) | AP5: =(IF(OR(N5=0,LEN(N5)=0),"",_xlfn.CONCAT(VLOOKUP(N5,$U$3:$X$230,4,FALSE)))) | AQ5: =(IF(OR(O5=0,LEN(O5)=0),"",_xlfn.CONCAT(VLOOKUP(O5,$U$3:$X$230,4,FALSE)))) | AR5: =(IF(OR(P5=0,LEN(P5)=0),"",_xlfn.CONCAT(VLOOKUP(P5,$U$3:$X$230,4,FALSE)))) | AS5: =(IF(OR(Q5=0,LEN(Q5)=0),"",_xlfn.CONCAT(VLOOKUP(Q5,$U$3:$X$230,4,FALSE)))) | AT5: =(IF(OR(R5=0,LEN(R5)=0),"",_xlfn.CONCAT(VLOOKUP(R5,$U$3:$X$230,4,FALSE)))) | AU5: =(IF(OR(S5=0,LEN(S5)=0),"",_xlfn.CONCAT(VLOOKUP(S5,$U$3:$X$230,4,FALSE)))) | AW5: =VLOOKUP(A5,'Updated Bios & Spouse Details'!$A$1:$J$193,6,FALSE) -> Wales & England | AX5: =VLOOKUP($A5,'Loyd List 1-190 - Edit'!$P$2:$AQ$220,AX$1,FALSE) -> 3 | AY5: =IF(ISNA(VLOOKUP(A5,'Data check lookup table'!$G$2:$V$73,13,FALSE))," - ",VLOOKUP(A5,'Data check lookup table'!$G$2:$V$73,13,FALSE)) -> - | AZ5: =TEXT(J5,"dd/mm/yyyy") -> 13/05/1858 | BA5: =(IF(OR(Q5=0,LEN(Q5)=0),"",_xlfn.CONCAT(", ",VLOOKUP(Q5,$U$3:$X$230,4,FALSE)))) | BB5: =(IF(OR(R5=0,LEN(R5)=0),"",_xlfn.CONCAT("; ",VLOOKUP(R5,$U$3:$X$230,4,FALSE)))) | BI5: 13/05/1858
